Workbook

Sheet Dashboard
A1: SOFTWAVES | C1: MODELO FINANCIERO 2025–2028
A2: Plan de Negocios — Resumen Ejecutivo Financiero
A4: Inversión Inicial | B4: Ingresos Año 1 (est.) | C4: TIR (5 años) | D4: VPN (5 años, 15%)
A5: ='Indicadores Financieros'!B5*-1 -> 281000 | B5: ='Proyección 3 Años'!B6 -> 56500 | C5: ='Indicadores Financieros'!B14 -> 1.1804593 | D5: ='Indicadores Financieros'!B16 -> 1371173.9
A7: Utilidad Bruta Año 1 | B7: Payback Estimado | C7: ROI Año 1 | D7: Utilidad Bruta Año 3
A8: ='Proyección 3 Años'!B14 -> 758000 | B8: Mes 5–6 | C8: ='Indicadores Financieros'!B15 -> 0.83378946 | D8: ='Proyección 3 Años'!D14 -> 1250000
A10: ► Ver hojas: Supuestos | Proyección Año 1 | Proyección 3 Años | Punto de Equilibrio | Indicadores Financieros

Sheet Supuestos
A1: SOFTWAVES — SUPUESTOS Y PARÁMETROS BASE
A2: Todos los montos en MXN. Celdas en azul = entradas editables.
A4: INVERSIÓN INICIAL
A5: Concepto | B5: Monto (MXN) | C5: Notas
A6: Constitución legal (S. de R.L. de C.V.) | B6: 8000 | C6: Notario público — incluyendo acta constitutiva y poderes
A7: Registro de marca ante IMPI | B7: 3500 | C7: Protección del nombre y logotipo SoftWaves
A8: Dominio, correos corporativos y hosting | B8: 2500 | C8: Infraestructura digital básica — costo anual
A9: Herramientas SaaS y licencias (1er año) | B9: 6000 | C9: GitHub, Jira, herramientas cloud de desarrollo
A10: PC potente 1 — Programación backend | B10: 25000 | C10: Ryzen 9 / i9, 32 GB RAM, RTX 3060 — escritorio
A11: PC potente 2 — Diseño y frontend | B11: 27000 | C11: Ryzen 9 / i9, 32 GB RAM, RTX 4060 + monitor profesional
A12: Laptop CEO (reuniones y trabajo remoto) | B12: 12000 | C12: Intel i7, 16 GB RAM — portátil gama media
A13: Laptop RRHH | B13: 11000 | C13: Intel i5, 8 GB RAM — portátil gama media
A14: Mac mini M2 Pro + monitor (desarrollo iOS) | B14: 28000 | C14: Entorno nativo Apple para apps iOS/macOS
A15: iPad Air (pruebas de apps móviles) | B15: 13000 | C15: Dispositivo de pruebas iOS/iPadOS
A16: iPhone 15 (pruebas de apps iOS) | B16: 16000 | C16: Dispositivo de pruebas para producción
A17: Mobiliario — escritorios y sillas ergonómicas | B17: 14000 | C17: 4 estaciones de trabajo + recepción
... A26: Imprevistos (10%) | B26: 25500 | C26: Reserva de contingencia
A27: TOTAL INVERSIÓN INICIAL | B27: =SUM(B6:B26) -> 280500
A29: COSTOS FIJOS MENSUALES POR FASE OPERATIVA
A30: Concepto de Costo | B30: Fase 1: Meses 1–6 (MXN/mes) | C30: Fase 2: Mes 7–Año 2+ (MXN/mes)
A31: Retiros socios fundadores (4 personas) | B31: 18000 | C31: 22000
A32: Recepcionista (sueldo bruto) | B32: 7500 | C32: 7500
A33: Renta de oficina | B33: 7000 | C33: 7000
A34: Servicios básicos (luz, agua, internet) | B34: 2500 | C34: 2500
A35: Servicio de limpieza | B35: 1500 | C35: 1500
A36: SaaS y herramientas digitales | B36: 2000 | C36: 3000
A37: Hosting clientes (cloud/servidores) | B37: 1000 | C37: 2000
A38: Publicidad y marketing digital | B38: 4500 | C38: 6500
A39: Gastos legales y contables (terceros) | B39: 1500 | C39: 2000
A40: Gastos varios | B40: 500 | C40: 500
A41: TOTAL COSTOS FIJOS MENSUALES | B41: =SUM(B31:B40) -> 46000 | C41: =SUM(C31:C40) -> 54500
A43: PRECIOS DE REFERENCIA Y MÁRGENES POR PRODUCTO
A44: Producto / Servicio | B44: Precio promedio (MXN) | C44: Costo variable estimado (MXN)
A45: Proyecto cerrado — Micro (POS, tienda) | B45: 22000 | C45: 4000
A46: Proyecto cerrado — Mediano (PyME) | B46: 60000 | C46: 15000
A47: Proyecto cerrado — Grande (complejo) | B47: 110000 | C47: 30000
A48: Renta mensual — Básica (por cliente/mes) | B48: 3000 | C48: 600
A49: Renta mensual — Avanzada (por cliente/mes) | B49: 6000 | C49: 1200
A50: Consultoría tecnológica (por hora) | B50: 900 | C50: 50
A51: IA add-on — complemento (por cliente/mes) | B51: 2500 | C51: 900
...

Sheet Proyección Año 1
A1: SOFTWAVES — PROYECCIÓN DE INGRESOS Y COSTOS AÑO 1 (MXN)
A2: Concepto | B2: Mes 1 | C2: Mes 2 | D2: Mes 3 | E2: Mes 4 | F2: Mes 5 | G2: Mes 6 | H2: Mes 7 | I2: Mes 8 | J2: Mes 9 | K2: Mes 10 | L2: Mes 11 | M2: Mes 12 | N2: TOTAL AÑO 1
A3: INGRESOS
A4: Proyectos cerrados | B4: 0 | C4: 18000 | D4: 28000 | E4: 35000 | F4: 37000 | G4: 45000 | H4: 50000 | I4: 50000 | J4: 56000 | K4: 58000 | L4: 63000 | M4: 70000 | N4: =SUM(B4:M4) -> 510000
A5: Renta mensual (acumulado de clientes) | B5: 0 | C5: 0 | D5: 2500 | E5: 5000 | F5: 7500 | G5: 10000 | H5: 12500 | I5: 15000 | J5: 17500 | K5: 20000 | L5: 22500 | M5: 25000 | N5: =SUM(B5:M5) -> 137500
A6: Consultoría por hora | B6: 3000 | C6: 3500 | D6: 4000 | E6: 4500 | F6: 5000 | G6: 5000 | H6: 5500 | I6: 5500 | J6: 6000 | K6: 6000 | L6: 6500 | M6: 6500 | N6: =SUM(B6:M6) -> 61000
A7: IA (add-on y licencias) | B7: 0 | C7: 0 | D7: 0 | E7: 0 | F7: 0 | G7: 2000 | H7: 2500 | I7: 3000 | J7: 3500 | K7: 4000 | L7: 4500 | M7: 5000 | N7: =SUM(B7:M7) -> 24500
A8: TOTAL INGRESOS | B8: =SUM(B4:B7) -> 3000 | C8: =SUM(C4:C7) -> 21500 | D8: =SUM(D4:D7) -> 34500 | E8: =SUM(E4:E7) -> 44500 | F8: =SUM(F4:F7) -> 49500 | G8: =SUM(G4:G7) -> 62000 | H8: =SUM(H4:H7) -> 70500 | I8: =SUM(I4:I7) -> 73500 | ... M8: =SUM(M4:M7) -> 106500 | N8: =SUM(B8:M8) -> 733000
A10: COSTOS
A11: Costos fijos operativos | B11: 46000 | C11: 46000 | D11: 46000 | E11: 46000 | F11: 46000 | G11: 46000 | H11: 54500 | I11: 54500 | J11: 54500 | K11: 54500 | L11: 54500 | M11: 54500 | N11: =SUM(B11:M11) -> 603000
A12: Costos variables (hosting clientes, APIs) | B12: 0 | C12: 2000 | D12: 3500 | E12: 5000 | F12: 5500 | G12: 7000 | H12: 9000 | I12: 9500 | J12: 11000 | K12: 11500 | L12: 12500 | M12: 14000 | N12: =SUM(B12:M12) -> 90500
A13: Pagos a freelancers (variable según proyecto) | B13: 0 | C13: 0 | D13: 0 | E13: 4000 | F13: 4500 | G13: 6000 | H13: 7000 | I13: 7000 | J13: 8000 | K13: 8500 | L13: 9000 | M13: 10000 | N13: =SUM(B13:M13) -> 64000
A14: TOTAL COSTOS | B14: =SUM(B11:B13) -> 46000 | C14: =SUM(C11:C13) -> 48000 | D14: =SUM(D11:D13) -> 49500 | E14: =SUM(E11:E13) -> 55000 | F14: =SUM(F11:F13) -> 56000 | G14: =SUM(G11:G13) -> 59000 | H14: =SUM(H11:H13) -> 70500 | I14: =SUM(I11:I13) -> 71000 | ... N14: =SUM(N11:N13) -> 757500
A16: UTILIDAD BRUTA DEL MES | B16: =B8-B14 -> -43000 | C16: =C8-C14 -> -26500 | D16: =D8-D14 -> -15000 | E16: =E8-E14 -> -10500 | F16: =F8-F14 -> -6500 | G16: =G8-G14 -> 3000 | H16: =H8-H14 -> 0 | I16: =I8-I14 -> 2500 | ... N16: =N8-N14 -> -24500
A17: FLUJO ACUMULADO (desde inversión inicial) | B17: =-Supuestos!$B$27+B16 -> -323500 | C17: =B17+C16 -> -350000 | D17: =C17+D16 -> -365000 | E17: =D17+E16 -> -375500 | F17: =E17+F16 -> -382000 | G17: =F17+G16 -> -379000 | H17: =G17+H16 -> -379000 | I17: =H17+I16 -> -376500 | J17: =I17+J16 -> -367000 | ... M17: =L17+M16 -> -305000

Sheet Proyección 3 Años
A1: SOFTWAVES — PROYECCIÓN FINANCIERA A 3 AÑOS (MXN)
A2: Concepto | B2: Año 1 | C2: Año 2 | D2: Año 3 | E2: Var. Año 2 vs 1
A3: INGRESOS
A4: Proyectos cerrados | B4: 456000 | C4: 700000 | D4: 1100000 | E4: =(C4-B4)/B4 -> 0.53508772
A5: Renta mensual (MRR) | B5: 135000 | C5: 420000 | D5: 700000 | E5: =(C5-B5)/B5 -> 2.1111111
A6: Consultoría | B6: 56500 | C6: 110000 | D6: 160000 | E6: =(C6-B6)/B6 -> 0.94690265
A7: IA (add-ons + licencias) | B7: 35500 | C7: 110000 | D7: 200000 | E7: =(C7-B7)/B7 -> 2.0985915
A8: TOTAL INGRESOS | B8: =SUM(B4:B7) -> 683000 | C8: =SUM(C4:C7) -> 1340000 | D8: =SUM(D4:D7) -> 2160000 | E8: =(C8-B8)/B8 -> 0.96193265
A10: COSTOS
A11: Costos fijos operativos | B11: 603000 | C11: 700000 | D11: 900000 | E11: =(C11-B11)/B11 -> 0.16086235
A12: Costos variables | B12: 91000 | C12: 130000 | D12: 190000 | E12: =(C12-B12)/B12 -> 0.42857143
A13: Pagos a freelancers | B13: 64000 | C13: 130000 | D13: 160000 | E13: =(C13-B13)/B13 -> 1.03125
A14: TOTAL COSTOS | B14: =SUM(B11:B13) -> 758000 | C14: =SUM(C11:C13) -> 960000 | D14: =SUM(D11:D13) -> 1250000 | E14: =(C14-B14)/B14 -> 0.26649077
A16: UTILIDAD BRUTA | B16: =B8-B14 -> -75000 | C16: =C8-C14 -> 380000 | D16: =D8-D14 -> 910000 | E16: =(C16-B16)/ABS(B16) -> 6.0666667
A17: Margen bruto (%) | B17: =B16/B8 -> -0.10980966 | C17: =C16/C8 -> 0.28358209 | D17: =D16/D8 -> 0.4212963
A19: OTROS INDICADORES
A20: Clientes activos (fin de año) | B20: 8–12 | C20: 18–26 | D20: 30–42
A21: Contratos de mantenimiento activos | B21: 6–8 | C21: 14–20 | D21: 25–35
A22: Colaboradores externos promedio/mes | B22: 2–3 | C22: 4–6 | D22: 7–10

Sheet Punto de Equilibrio
A1: SOFTWAVES — ANÁLISIS DE PUNTO DE EQUILIBRIO
A3: Parámetros del Análisis
A4: Costos fijos mensuales (Fase 1): | B4: 46000
A5: Margen de contribución promedio: | B5: 0.72
A6: Ingreso mínimo para equilibrio: | B6: =B4/B5 -> 63888.889
A8: Análisis Mensual — Año 1
A9: Mes | B9: Costos Fijos | C9: Ingresos Reales | D9: Margen Contrib. | E9: ¿Equilibrio? | F9: Ingreso Req.
A10: Mes 1 | B10: 46000 | C10: 3000 | D10: =C10-B10 -> -43000 | E10: NO | F10: =$B$4 -> 46000
A11: Mes 2 | B11: 46000 | C11: 21500 | D11: =C11-B11 -> -24500 | E11: NO | F11: =$B$4 -> 46000
A12: Mes 3 | B12: 46000 | C12: 34500 | D12: =C12-B12 -> -11500 | E12: NO | F12: =$B$4 -> 46000
A13: Mes 4 | B13: 46000 | C13: 44500 | D13: =C13-B13 -> -1500 | E13: NO | F13: =$B$4 -> 46000
A14: Mes 5 | B14: 46000 | C14: 49500 | D14: =C14-B14 -> 3500 | E14: SI ✓ | F14: =$B$4 -> 46000
A15: Mes 6 | B15: 46000 | C15: 62000 | D15: =C15-B15 -> 16000 | E15: SI ✓ | F15: =$B$4 -> 46000
A16: Mes 7 | B16: 54500 | C16: 70500 | D16: =C16-B16 -> 16000 | E16: SI ✓ | F16: =$B$4 -> 46000
A17: Mes 8 | B17: 54500 | C17: 73500 | D17: =C17-B17 -> 19000 | E17: SI ✓ | F17: =$B$4 -> 46000
A18: Mes 9 | B18: 54500 | C18: 83000 | D18: =C18-B18 -> 28500 | E18: SI ✓ | F18: =$B$4 -> 46000
A19: Mes 10 | B19: 54500 | C19: 88000 | D19: =C19-B19 -> 33500 | E19: SI ✓ | F19: =$B$4 -> 46000
A20: Mes 11 | B20: 54500 | C20: 96500 | D20: =C20-B20 -> 42000 | E20: SI ✓ | F20: =$B$4 -> 46000
A21: Mes 12 | B21: 54500 | C21: 106500 | D21: =C21-B21 -> 52000 | E21: SI ✓ | F21: =$B$4 -> 46000

Sheet Indicadores Financieros
A1: SOFTWAVES — INDICADORES DE RENTABILIDAD E INVERSIÓN
A3: FLUJOS NETOS DE EFECTIVO (BASE DE CÁLCULO)
A4: Período | B4: Flujo Neto (MXN) | C4: Descripción
A5: Año 0 (inversión) | B5: -281000 | C5: Inversión inicial de los socios fundadores (equipos + oficina + capital)
A6: Año 1 | B6: -25000 | C6: Año de arranque: ingresos ~$733k vs costos ~$758k (año de posicionamiento)
A7: Año 2 | B7: 500000 | C7: Utilidad neta estimada Año 2 (base de clientes consolidada)
A8: Año 3 | B8: 900000 | C8: Utilidad neta estimada Año 3 (crecimiento + ingresos recurrentes)
A9: Año 4 (proyectado) | B9: 1400000 | C9: Proyección conservadora con cartera establecida
A10: Año 5 (proyectado) | B10: 1900000 | C10: Proyección con producto SaaS IA en operación
A12: INDICADORES DE RENTABILIDAD (CALCULADOS AUTOMÁTICAMENTE)
A13: Indicador | B13: Resultado | C13: Interpretación
A14: TIR — Tasa Interna de Retorno (5 años) | B14: =IRR(B5:B10) -> 1.1804593 | C14: Rendimiento anual de la inversión. Por encima del 30% es excelente para una startup.
A15: TIR (3 años) | B15: =IRR(B5:B8) -> 0.83378946 | C15: TIR considerando solo los primeros 3 años de operación.
A16: VPN — Valor Presente Neto (5 años, tasa 15%) | B16: =NPV(Supuestos!$B$56,B10)+B5 -> 1371173.9 | C16: Valor actual de las ganancias futuras descontadas. Positivo = proyecto viable.
A17: VPN (3 años) | B17: =NPV(Supuestos!$B$56,B6:B8)+B5 -> 667097.31 | C17: VPN solo con los 3 primeros años. Positivo confirma rentabilidad a corto plazo.
A18: Período de Recuperación (Payback) | B18: ~18 meses (ver hoja Punto de Equilibrio) | C18: La inversión se recupera aproximadamente a mitad del Año 2, cuando el flujo acumulado vuelve a positivo.
A19: ROI — Retorno sobre la Inversión (Año 2) | B19: =B7/ABS(B5) -> 1.7793594 | C19: Cuántas veces se recupera la inversión en el Año 2 (Año 1 es de posicionamiento con utilidad casi neutra).
A20: Relación Beneficio / Costo (3 años) | B20: =(B6+B7+B8)/ABS(B5) -> 4.8932384 | C20: Por cada peso invertido, cuántos pesos de beneficio se obtienen en 3 años.
A21: Margen neto promedio (Año 1) | B21: 40.0% | C21: Porcentaje de cada peso de ingreso que se convierte en utilidad (estimado Año 1).
A23: NOTAS Y SUPUESTOS CLAVE
A24: • Los flujos de caja son estimaciones conservadoras basadas en los supuestos de la hoja 'Supuestos'.
A25: • La TIR es alta porque el software tiene márgenes elevados. Con inversión ~$281k, la TIR baja a rango justificable (~60–90%) vs. la TIR irreal de un escenario sin oficina.
A26: • El VPN puede ajustarse cambiando la tasa de descuento en la celda amarilla de la hoja 'Supuestos'.
A27: • Los flujos Años 4-5 son proyecciones indicativas; actualizar conforme avance la operación real.
A28: • Los pagos a freelancers son costos variables que solo se activan cuando hay proyectos activos.
